Workbook

Sheet Sheet4
A3: Row Labels | B3: Sum of Shell_weight | C3: Sum of Viscera_weight | D3: Sum of Shucked_weight
A4: Florida Atlantic Coast | B4: 20.24 | C4: 15.2685 | D4: 28.787
A5: Florida Gulf Coast | B5: 16.8305 | C5: 12.6895 | D5: 24.8105
A6: Great Lakes | B6: 18.1175 | C6: 13.886 | D6: 27.6815
A7: Gulf of Mexico | B7: 21.441 | C7: 16.165 | D7: 31.0675
A8: Mid-Atlantic | B8: 16.824 | C8: 12.5455 | D8: 23.9485
A9: North Pacific | B9: 19.0565 | C9: 14.728 | D9: 29.5855
A10: Northeast | B10: 18.1885 | C10: 13.658 | D10: 26.9
A11: Pacific | B11: 19.2805 | C11: 14.6195 | D11: 28.4705
A12: Southeast | B12: 21.2935 | C12: 15.7005 | D12: 30.4985
A13: West Coast | B13: 17.6735 | C13: 13.292 | D13: 26.6915
A14: (blank)
A15: Grand Total | B15: 188.9455 | C15: 142.5525 | D15: 278.441

Sheet Personal Data
A1: Abalone ID | B1: Gender | C1: Length | D1: Diameter | E1: Height | F1: Whole_weight | G1: Shucked_weight | H1: Viscera_weight | I1: Shell_weight | J1: Rings | K1: Collector | L1: Collector_First | M1: Collector_last | N1: Collector_organization | O1: Water | Q1: Feb_temp
A2: 2424 | B2: F | C2: 0.41 | D2: 0.315 | E2: 0.11 | F2: 0.321 | G2: 0.1255 | H2: 0.0655 | I2: 0.095 | J2: 10 | K2: 9 | L2: Danica | M2: Tyler | N2: University of Florida | O2: 9 | P2: North Pacific | Q2: 1.9
A3: 484 | B3: F | C3: 0.58 | D3: 0.46 | E3: 0.15 | F3: 0.9955 | G3: 0.429 | H3: 0.212 | I3: 0.26 | J3: 19 | K3: 10 | L3: Hazel | M3: Villa | N3: University of Minnesota | O3: 9 | P3: North Pacific | Q3: 1.9
A4: 2948 | B4: F | C4: 0.635 | D4: 0.485 | E4: 0.18 | F4: 1.1795 | G4: 0.4785 | H4: 0.2775 | I4: 0.355 | J4: 10 | K4: 4 | L4: Nate | M4: Craig | N4: NOAA Fisheries | O4: 7 | P4: Great Lakes | Q4: 2.5
A5: 2404 | B5: F | C5: 0.29 | D5: 0.225 | E5: 0.08 | F5: 0.1295 | G5: 0.0535 | H5: 0.026 | I5: 0.045 | J5: 10 | K5: 13 | L5: Betty | M5: Berg | N5: University of Houston | O5: 8 | P5: West Coast | Q5: 12.3
A6: 1480 | B6: F | C6: 0.575 | D6: 0.46 | E6: 0.165 | F6: 0.9155 | G6: 0.4005 | H6: 0.2465 | I6: 0.2385 | J6: 8 | K6: 6 | L6: Martin | M6: Gaines | N6: San Diego State University | O6: 3 | P6: Northeast | Q6: 3.6
A7: 1150 | B7: F | C7: 0.58 | D7: 0.45 | E7: 0.155 | F7: 0.93 | G7: 0.385 | H7: 0.246 | I7: 0.265 | J7: 9 | K7: 2 | L7: Tiegan | M7: Davie | N7: University of California, Davis | O7: 2 | P7: Florida Gulf Coast | Q7: 18
A8: 1319 | B8: F | C8: 0.555 | D8: 0.43 | E8: 0.14 | F8: 0.7665 | G8: 0.341 | H8: 0.165 | I8: 0.23 | J8: 9 | K8: 3 | L8: Inaya | M8: Bernard | N8: Stanford University | O8: 3 | P8: Northeast | Q8: 3.6
A9: 2110 | B9: F | C9: 0.62 | D9: 0.49 | E9: 0.17 | F9: 1.2105 | G9: 0.5185 | H9: 0.2555 | I9: 0.335 | J9: 13 | K9: 8 | L9: Kali | M9: Metcalfe | N9: Mote Marine Laboratory | O9: 8 | P9: West Coast | Q9: 12.3
A10: 1000 | B10: F | C10: 0.595 | D10: 0.47 | E10: 0.155 | F10: 1.121 | G10: 0.4515 | H10: 0.178 | I10: 0.155 | J10: 11 | K10: 12 | L10: Rebecca | M10: Bennett | N10: University of Houston | O10: 7 | P10: Great Lakes | Q10: 2.5
A11: 228 | B11: F | C11: 0.365 | D11: 0.27 | E11: 0.085 | F11: 0.205 | G11: 0.078 | H11: 0.0485 | I11: 0.07 | J11: 7 | K11: 2 | L11: Tiegan | M11: Davie | N11: University of California, Davis | O11: 4 | P11: Mid-Atlantic | Q11: 6.1
A12: 3945 | B12: F | C12: 0.55 | D12: 0.44 | E12: 0.16 | F12: 0.991 | G12: 0.348 | H12: 0.168 | I12: 0.375 | J12: 20 | K12: 8 | L12: Kali | M12: Metcalfe | N12: Mote Marine Laboratory | O12: 1 | P12: Florida Atlantic Coast | Q12: 22.1
A13: 1308 | B13: F | C13: 0.545 | D13: 0.435 | E13: 0.135 | F13: 0.7715 | G13: 0.372 | H13: 0.148 | I13: 0.227 | J13: 8 | K13: 12 | L13: Rebecca | M13: Bennett | N13: University of Houston | O13: 5 | P13: Southeast | Q13: 12.8
... A1001: 2207 | B1001: M | C1001: 0.29 | D1001: 0.225 | E1001: 0.075 | F1001: 0.14 | G1001: 0.0515 | H1001: 0.0235 | I1001: 0.04 | J1001: 5 | K1001: 3 | L1001: Inaya | M1001: Bernard | N1001: Stanford University | O1001: 5 | P1001: Southeast | Q1001: 12.8
B1002: M

Sheet Isba_Asghar_ExcData.xlsx (2)
A1: Abalone_id | B1: Gender | C1: Length | D1: Diameter | E1: Height | F1: Whole Weight | G1: Shucked_weight | H1: Viscera_weight | I1: Shell_weight | J1: Rings | K1: Collector | L1: Collector_First | M1: Collector_last | N1: Collector_organization | O1: Water | P1: Water_region | Q1: Feb_temp
A2: 2424 | B2: F | C2: 0.41 | D2: 0.315 | E2: 0.11 | F2: 0.321 | G2: 0.1255 | H2: 0.0655 | I2: 0.095 | J2: 10 | K2: 9 | L2: Danica | M2: Tyler | N2: University of Florida | O2: 9 | P2: North Pacific | Q2: 1.9
A3: 484 | B3: F | C3: 0.58 | D3: 0.46 | E3: 0.15 | F3: 0.9955 | G3: 0.429 | H3: 0.212 | I3: 0.26 | J3: 19 | K3: 10 | L3: Hazel | M3: Villa | N3: University of Minnesota | O3: 9 | P3: North Pacific | Q3: 1.9
A4: 2948 | B4: F | C4: 0.635 | D4: 0.485 | E4: 0.18 | F4: 1.1795 | G4: 0.4785 | H4: 0.2775 | I4: 0.355 | J4: 10 | K4: 4 | L4: Nate | M4: Craig | N4: NOAA Fisheries | O4: 7 | P4: Great Lakes | Q4: 2.5
A5: 2404 | B5: F | C5: 0.29 | D5: 0.225 | E5: 0.08 | F5: 0.1295 | G5: 0.0535 | H5: 0.026 | I5: 0.045 | J5: 10 | K5: 13 | L5: Betty | M5: Berg | N5: University of Houston | O5: 8 | P5: West Coast | Q5: 12.3
A6: 1480 | B6: F | C6: 0.575 | D6: 0.46 | E6: 0.165 | F6: 0.9155 | G6: 0.4005 | H6: 0.2465 | I6: 0.2385 | J6: 8 | K6: 6 | L6: Martin | M6: Gaines | N6: San Diego State University | O6: 3 | P6: Northeast | Q6: 3.6
A7: 1150 | B7: F | C7: 0.58 | D7: 0.45 | E7: 0.155 | F7: 0.93 | G7: 0.385 | H7: 0.246 | I7: 0.265 | J7: 9 | K7: 2 | L7: Tiegan | M7: Davie | N7: University of California, Davis | O7: 2 | P7: Florida Gulf Coast | Q7: 18
A8: 1319 | B8: F | C8: 0.555 | D8: 0.43 | E8: 0.14 | F8: 0.7665 | G8: 0.341 | H8: 0.165 | I8: 0.23 | J8: 9 | K8: 3 | L8: Inaya | M8: Bernard | N8: Stanford University | O8: 3 | P8: Northeast | Q8: 3.6
A9: 2110 | B9: F | C9: 0.62 | D9: 0.49 | E9: 0.17 | F9: 1.2105 | G9: 0.5185 | H9: 0.2555 | I9: 0.335 | J9: 13 | K9: 8 | L9: Kali | M9: Metcalfe | N9: Mote Marine Laboratory | O9: 8 | P9: West Coast | Q9: 12.3
A10: 1000 | B10: F | C10: 0.595 | D10: 0.47 | E10: 0.155 | F10: 1.121 | G10: 0.4515 | H10: 0.178 | I10: 0.155 | J10: 11 | K10: 12 | L10: Rebecca | M10: Bennett | N10: University of Houston | O10: 7 | P10: Great Lakes | Q10: 2.5
A11: 228 | B11: F | C11: 0.365 | D11: 0.27 | E11: 0.085 | F11: 0.205 | G11: 0.078 | H11: 0.0485 | I11: 0.07 | J11: 7 | K11: 2 | L11: Tiegan | M11: Davie | N11: University of California, Davis | O11: 4 | P11: Mid-Atlantic | Q11: 6.1
A12: 3945 | B12: F | C12: 0.55 | D12: 0.44 | E12: 0.16 | F12: 0.991 | G12: 0.348 | H12: 0.168 | I12: 0.375 | J12: 20 | K12: 8 | L12: Kali | M12: Metcalfe | N12: Mote Marine Laboratory | O12: 1 | P12: Florida Atlantic Coast | Q12: 22.1
A13: 1308 | B13: F | C13: 0.545 | D13: 0.435 | E13: 0.135 | F13: 0.7715 | G13: 0.372 | H13: 0.148 | I13: 0.227 | J13: 8 | K13: 12 | L13: Rebecca | M13: Bennett | N13: University of Houston | O13: 5 | P13: Southeast | Q13: 12.8
... A1001: 2207 | B1001: M | C1001: 0.29 | D1001: 0.225 | E1001: 0.075 | F1001: 0.14 | G1001: 0.0515 | H1001: 0.0235 | I1001: 0.04 | J1001: 5 | K1001: 3 | L1001: Inaya | M1001: Bernard | N1001: Stanford University | O1001: 5 | P1001: Southeast | Q1001: 12.8
B1002: M

Sheet Categorization
A1: Abalone_id | B1: Gender | C1: Length | D1: Diameter | E1: Height | F1: Whole_weight | G1: Shucked_weight | H1: Viscera_weight | I1: Shell_weight | J1: Rings | K1: Collector | L1: Collector_First | M1: Collector_last | N1: Collector_organization | O1: Water | P1: Water_region | Q1: Feb_temp | R1: Category
A2: 2110 | B2: F | C2: 0.62 | D2: 0.49 | E2: 0.17 | F2: 1.2105 | G2: 0.5185 | H2: 0.2555 | I2: 0.335 | J2: 13 | K2: 8 | L2: Kali | M2: Metcalfe | N2: Mote Marine Laboratory | O2: 8 | P2: West Coast | Q2: 12.3 | R2: =IF(OR(AND(J2 > 15, B2 = "Infant"), AND(D2 = "Male", C2 > 0.75), OR(I2 > 0.8, G2 > 0.5), G2 > 1.2), "I", IF(OR(AND(I2 < 0.4, G2 < 0.4), AND(J2 > 15, D2 = "Male"), AND(J2 > 18, D2 = "Female"), C2 < 0.36), "II", "III")) -> I
A3: 1671 | B3: F | C3: 0.61 | D3: 0.485 | E3: 0.15 | F3: 1.2405 | G3: 0.6025 | H3: 0.2915 | I3: 0.3085 | J3: 12 | K3: 13 | L3: Betty | M3: Berg | N3: University of Houston | O3: 10 | P3: Pacific | Q3: 24.1 | R3: =IF(OR(AND(J3 > 15, B3 = "Infant"), AND(D3 = "Male", C3 > 0.75), OR(I3 > 0.8, G3 > 0.5), G3 > 1.2), "I", IF(OR(AND(I3 < 0.4, G3 < 0.4), AND(J3 > 15, D3 = "Male"), AND(J3 > 18, D3 = "Female"), C3 < 0.36), "II", "III")) -> I
A4: 1202 | B4: F | C4: 0.72 | D4: 0.565 | E4: 0.145 | F4: 1.187 | G4: 0.691 | H4: 0.1945 | I4: 0.2685 | J4: 8 | K4: 7 | L4: Iona | M4: Connolly | N4: Florida Atlantic University | O4: 2 | P4: Florida Gulf Coast | Q4: 18 | R4: =IF(OR(AND(J4 > 15, B4 = "Infant"), AND(D4 = "Male", C4 > 0.75), OR(I4 > 0.8, G4 > 0.5), G4 > 1.2), "I", IF(OR(AND(I4 < 0.4, G4 < 0.4), AND(J4 > 15, D4 = "Male"), AND(J4 > 18, D4 = "Female"), C4 < 0.36), "II", "III")) -> I
A5: 2664 | B5: F | C5: 0.57 | D5: 0.45 | E5: 0.135 | F5: 1.02 | G5: 0.546 | H5: 0.204 | I5: 0.25 | J5: 9 | K5: 7 | L5: Iona | M5: Connolly | N5: Florida Atlantic University | O5: 5 | P5: Southeast | Q5: 12.8 | R5: =IF(OR(AND(J5 > 15, B5 = "Infant"), AND(D5 = "Male", C5 > 0.75), OR(I5 > 0.8, G5 > 0.5), G5 > 1.2), "I", IF(OR(AND(I5 < 0.4, G5 < 0.4), AND(J5 > 15, D5 = "Male"), AND(J5 > 18, D5 = "Female"), C5 < 0.36), "II", "III")) -> I
A6: 1168 | B6: F | C6: 0.62 | D6: 0.47 | E6: 0.135 | F6: 1.0195 | G6: 0.5315 | H6: 0.2005 | I6: 0.2475 | J6: 8 | K6: 11 | L6: Naima | M6: Reyes | N6: University of Houston | O6: 9 | P6: North Pacific | Q6: 1.9 | R6: =IF(OR(AND(J6 > 15, B6 = "Infant"), AND(D6 = "Male", C6 > 0.75), OR(I6 > 0.8, G6 > 0.5), G6 > 1.2), "I", IF(OR(AND(I6 < 0.4, G6 < 0.4), AND(J6 > 15, D6 = "Male"), AND(J6 > 18, D6 = "Female"), C6 < 0.36), "II", "III")) -> I
A7: 488 | B7: F | C7: 0.625 | D7: 0.515 | E7: 0.15 | F7: 1.2415 | G7: 0.5235 | H7: 0.3065 | I7: 0.36 | J7: 15 | K7: 1 | L7: Jan | M7: Odom | N7: University of Houston | O7: 7 | P7: Great Lakes | Q7: 2.5 | R7: =IF(OR(AND(J7 > 15, B7 = "Infant"), AND(D7 = "Male", C7 > 0.75), OR(I7 > 0.8, G7 > 0.5), G7 > 1.2), "I", IF(OR(AND(I7 < 0.4, G7 < 0.4), AND(J7 > 15, D7 = "Male"), AND(J7 > 18, D7 = "Female"), C7 < 0.36), "II", "III")) -> I
A8: 341 | B8: F | C8: 0.575 | D8: 0.455 | E8: 0.145 | F8: 1.165 | G8: 0.581 | H8: 0.2275 | I8: 0.3 | J8: 14 | K8: 13 | L8: Betty | M8: Berg | N8: University of Houston | O8: 4 | P8: Mid-Atlantic | Q8: 6.1 | R8: =IF(OR(AND(J8 > 15, B8 = "Infant"), AND(D8 = "Male", C8 > 0.75), OR(I8 > 0.8, G8 > 0.5), G8 > 1.2), "I", IF(OR(AND(I8 < 0.4, G8 < 0.4), AND(J8 > 15, D8 = "Male"), AND(J8 > 18, D8 = "Female"), C8 < 0.36), "II", "III")) -> I
A9: 3740 | B9: F | C9: 0.65 | D9: 0.525 | E9: 0.165 | F9: 1.238 | G9: 0.647 | H9: 0.2485 | I9: 0.3005 | J9: 9 | K9: 7 | L9: Iona | M9: Connolly | N9: Florida Atlantic University | O9: 3 | P9: Northeast | Q9: 3.6 | R9: =IF(OR(AND(J9 > 15, B9 = "Infant"), AND(D9 = "Male", C9 > 0.75), OR(I9 > 0.8, G9 > 0.5), G9 > 1.2), "I", IF(OR(AND(I9 < 0.4, G9 < 0.4), AND(J9 > 15, D9 = "Male"), AND(J9 > 18, D9 = "Female"), C9 < 0.36), "II", "III")) -> I
A10: 2990 | B10: F | C10: 0.56 | D10: 0.425 | E10: 0.135 | F10: 0.9415 | G10: 0.509 | H10: 0.2015 | I10: 0.1975 | J10: 9 | K10: 15 | L10: Conan | M10: Dalton | N10: University of Houston | O10: 8 | P10: West Coast | Q10: 12.3 | R10: =IF(OR(AND(J10 > 15, B10 = "Infant"), AND(D10 = "Male", C10 > 0.75), OR(I10 > 0.8, G10 > 0.5), G10 > 1.2), "I", IF(OR(AND(I10 < 0.4, G10 < 0.4), AND(J10 > 15, D10 = "Male"), AND(J10 > 18, D10 = "Female"), C10 < 0.36), "II", "III")) -> I
A11: 2531 | B11: F | C11: 0.6 | D11: 0.485 | E11: 0.165 | F11: 1.1405 | G11: 0.587 | H11: 0.2175 | I11: 0.288 | J11: 9 | K11: 12 | L11: Rebecca | M11: Bennett | N11: University of Houston | O11: 8 | P11: West Coast | Q11: 12.3 | R11: =IF(OR(AND(J11 > 15, B11 = "Infant"), AND(D11 = "Male", C11 > 0.75), OR(I11 > 0.8, G11 > 0.5), G11 > 1.2), "I", IF(OR(AND(I11 < 0.4, G11 < 0.4), AND(J11 > 15, D11 = "Male"), AND(J11 > 18, D11 = "Female"), C11 < 0.36), "II", "III")) -> I
A12: 2605 | B12: F | C12: 0.62 | D12: 0.485 | E12: 0.175 | F12: 1.2155 | G12: 0.545 | H12: 0.253 | I12: 0.345 | J12: 10 | K12: 5 | L12: Haniya | M12: Talley | N12: Prince William Sound Science Center | O12: 5 | P12: Southeast | Q12: 12.8 | R12: =IF(OR(AND(J12 > 15, B12 = "Infant"), AND(D12 = "Male", C12 > 0.75), OR(I12 > 0.8, G12 > 0.5), G12 > 1.2), "I", IF(OR(AND(I12 < 0.4, G12 < 0.4), AND(J12 > 15, D12 = "Male"), AND(J12 > 18, D12 = "Female"), C12 < 0.36), "II", "III")) -> I
A13: 1807 | B13: F | C13: 0.625 | D13: 0.49 | E13: 0.185 | F13: 1.169 | G13: 0.5275 | H13: 0.2535 | I13: 0.344 | J13: 11 | K13: 7 | L13: Iona | M13: Connolly | N13: Florida Atlantic University | O13: 1 | P13: Florida Atlantic Coast | Q13: 22.1 | R13: =IF(OR(AND(J13 > 15, B13 = "Infant"), AND(D13 = "Male", C13 > 0.75), OR(I13 > 0.8, G13 > 0.5), G13 > 1.2), "I", IF(OR(AND(I13 < 0.4, G13 < 0.4), AND(J13 > 15, D13 = "Male"), AND(J13 > 18, D13 = "Female"), C13 < 0.36), "II", "III")) -> I
... A69: 4083 | B69: M | C69: 0.565 | D69: 0.465 | E69: 0.15 | F69: 1.1815 | G69: 0.581 | H69: 0.2215 | I69: 0.3095 | J69: 9 | K69: 9 | L69: Danica | M69: Tyler | N69: University of Florida | O69: 7 | P69: Great Lakes | Q69: 2.5 | R69: =IF(OR(AND(J69 > 15, B69 = "Infant"), AND(D69 = "Male", C69 > 0.75), OR(I69 > 0.8, G69 > 0.5), G69 > 1.2), "I", IF(OR(AND(I69 < 0.4, G69 < 0.4), AND(J69 > 15, D69 = "Male"), AND(J69 > 18, D69 = "Female"), C69 < 0.36), "II", "III")) -> I
A74: Abalone_id | B74: Gender | C74: Length | D74: Diameter | E74: Height | F74: Whole_weight | G74: Shucked_weight | H74: Viscera_weight | I74: Shell_weight | J74: Rings | K74: Collector | L74: Collector_First | M74: Collector_last | N74: Collector_organization | O74: Water | P74: Water_region | Q74: Feb_temp | R74: Category
A75: 2424 | B75: F | C75: 0.41 | D75: 0.315 | E75: 0.11 | F75: 0.321 | G75: 0.1255 | H75: 0.0655 | I75: 0.095 | J75: 10 | K75: 9 | L75: Danica | M75: Tyler | N75: University of Florida | O75: 9 | P75: North Pacific | Q75: 1.9 | R75: =IF(OR(AND(J75 > 15, B75 = "Infant"), AND(D75 = "Male", C75 > 0.75), OR(I75 > 0.8, G75 > 0.5), G75 > 1.2), "I", IF(OR(AND(I75 < 0.4, G75 < 0.4), AND(J75 > 15, D75 = "Male"), AND(J75 > 18, D75 = "Female"), C75 < 0.36), "II", "III")) -> II
A76: 2404 | B76: F | C76: 0.29 | D76: 0.225 | E76: 0.08 | F76: 0.1295 | G76: 0.0535 | H76: 0.026 | I76: 0.045 | J76: 10 | K76: 13 | L76: Betty | M76: Berg | N76: University of Houston | O76: 8 | P76: West Coast | Q76: 12.3 | R76: =IF(OR(AND(J76 > 15, B76 = "Infant"), AND(D76 = "Male", C76 > 0.75), OR(I76 > 0.8, G76 > 0.5), G76 > 1.2), "I", IF(OR(AND(I76 < 0.4, G76 < 0.4), AND(J76 > 15, D76 = "Male"), AND(J76 > 18, D76 = "Female"), C76 < 0.36), "II", "III")) -> II
A77: 1150 | B77: F | C77: 0.58 | D77: 0.45 | E77: 0.155 | F77: 0.93 | G77: 0.385 | H77: 0.246 | I77: 0.265 | J77: 9 | K77: 2 | L77: Tiegan | M77: Davie | N77: University of California, Davis | O77: 2 | P77: Florida Gulf Coast | Q77: 18 | R77: =IF(OR(AND(J77 > 15, B77 = "Infant"), AND(D77 = "Male", C77 > 0.75), OR(I77 > 0.8, G77 > 0.5), G77 > 1.2), "I", IF(OR(AND(I77 < 0.4, G77 < 0.4), AND(J77 > 15, D77 = "Male"), AND(J77 > 18, D77 = "Female"), C77 < 0.36), "II", "III")) -> II
A78: 1319 | B78: F | C78: 0.555 | D78: 0.43 | E78: 0.14 | F78: 0.7665 | G78: 0.341 | H78: 0.165 | I78: 0.23 | J78: 9 | K78: 3 | L78: Inaya | M78: Bernard | N78: Stanford University | O78: 3 | P78: Northeast | Q78: 3.6 | R78: =IF(OR(AND(J78 > 15, B78 = "Infant"), AND(D78 = "Male", C78 > 0.75), OR(I78 > 0.8, G78 > 0.5), G78 > 1.2), "I", IF(OR(AND(I78 < 0.4, G78 < 0.4), AND(J78 > 15, D78 = "Male"), AND(J78 > 18, D78 = "Female"), C78 < 0.36), "II", "III")) -> II
A79: 228 | B79: F | C79: 0.365 | D79: 0.27 | E79: 0.085 | F79: 0.205 | G79: 0.078 | H79: 0.0485 | I79: 0.07 | J79: 7 | K79: 2 | L79: Tiegan | M79: Davie | N79: University of California, Davis | O79: 4 | P79: Mid-Atlantic | Q79: 6.1 | R79: =IF(OR(AND(J79 > 15, B79 = "Infant"), AND(D79 = "Male", C79 > 0.75), OR(I79 > 0.8, G79 > 0.5), G79 > 1.2), "I", IF(OR(AND(I79 < 0.4, G79 < 0.4), AND(J79 > 15, D79 = "Male"), AND(J79 > 18, D79 = "Female"), C79 < 0.36), "II", "III")) -> II
A80: 3945 | B80: F | C80: 0.55 | D80: 0.44 | E80: 0.16 | F80: 0.991 | G80: 0.348 | H80: 0.168 | I80: 0.375 | J80: 20 | K80: 8 | L80: Kali | M80: Metcalfe | N80: Mote Marine Laboratory | O80: 1 | P80: Florida Atlantic Coast | Q80: 22.1 | R80: =IF(OR(AND(J80 > 15, B80 = "Infant"), AND(D80 = "Male", C80 > 0.75), OR(I80 > 0.8, G80 > 0.5), G80 > 1.2), "I", IF(OR(AND(I80 < 0.4, G80 < 0.4), AND(J80 > 15, D80 = "Male"), AND(J80 > 18, D80 = "Female"), C80 < 0.36), "II", "III")) -> II
A81: 1308 | B81: F | C81: 0.545 | D81: 0.435 | E81: 0.135 | F81: 0.7715 | G81: 0.372 | H81: 0.148 | I81: 0.227 | J81: 8 | K81: 12 | L81: Rebecca | M81: Bennett | N81: University of Houston | O81: 5 | P81: Southeast | Q81: 12.8 | R81: =IF(OR(AND(J81 > 15, B81 = "Infant"), AND(D81 = "Male", C81 > 0.75), OR(I81 > 0.8, G81 > 0.5), G81 > 1.2), "I", IF(OR(AND(I81 < 0.4, G81 < 0.4), AND(J81 > 15, D81 = "Male"), AND(J81 > 18, D81 = "Female"), C81 < 0.36), "II", "III")) -> II
A82: 2895 | B82: F | C82: 0.54 | D82: 0.425 | E82: 0.13 | F82: 0.8155 | G82: 0.3675 | H82: 0.1365 | I82: 0.246 | J82: 11 | K82: 8 | L82: Kali | M82: Metcalfe | N82: Mote Marine Laboratory | O82: 4 | P82: Mid-Atlantic | Q82: 6.1 | R82: =IF(OR(AND(J82 > 15, B82 = "Infant"), AND(D82 = "Male", C82 > 0.75), OR(I82 > 0.8, G82 > 0.5), G82 > 1.2), "I", IF(OR(AND(I82 < 0.4, G82 < 0.4), AND(J82 > 15, D82 = "Male"), AND(J82 > 18, D82 = "Female"), C82 < 0.36), "II", "III")) -> II
A83: 3411 | B83: F | C83: 0.415 | D83: 0.31 | E83: 0.105 | F83: 0.3595 | G83: 0.167 | H83: 0.083 | I83: 0.0915 | J83: 6 | K83: 7 | L83: Iona | M83: Connolly | N83: Florida Atlantic University | O83: 9 | P83: North Pacific | Q83: 1.9 | R83: =IF(OR(AND(J83 > 15, B83 = "Infant"), AND(D83 = "Male", C83 > 0.75), OR(I83 > 0.8, G83 > 0.5), G83 > 1.2), "I", IF(OR(AND(I83 < 0.4, G83 < 0.4), AND(J83 > 15, D83 = "Male"), AND(J83 > 18, D83 = "Female"), C83 < 0.36), "II", "III")) -> II
A84: 2764 | B84: F | C84: 0.55 | D84: 0.425 | E84: 0.135 | F84: 0.656 | G84: 0.257 | H84: 0.17 | I84: 0.203 | J84: 10 | K84: 11 | L84: Naima | M84: Reyes | N84: University of Houston | O84: 1 | P84: Florida Atlantic Coast | Q84: 22.1 | R84: =IF(OR(AND(J84 > 15, B84 = "Infant"), AND(D84 = "Male", C84 > 0.75), OR(I84 > 0.8, G84 > 0.5), G84 > 1.2), "I", IF(OR(AND(I84 < 0.4, G84 < 0.4), AND(J84 > 15, D84 = "Male"), AND(J84 > 18, D84 = "Female"), C84 < 0.36), "II", "III")) -> II
A85: 3342 | B85: F | C85: 0.49 | D85: 0.39 | E85: 0.135 | F85: 0.59 | G85: 0.215 | H85: 0.125 | I85: 0.1845 | J85: 12 | K85: 3 | L85: Inaya | M85: Bernard | N85: Stanford University | O85: 6 | P85: Gulf of Mexico | Q85: 14.1 | R85: =IF(OR(AND(J85 > 15, B85 = "Infant"), AND(D85 = "Male", C85 > 0.75), OR(I85 > 0.8, G85 > 0.5), G85 > 1.2), "I", IF(OR(AND(I85 < 0.4, G85 < 0.4), AND(J85 > 15, D85 = "Male"), AND(J85 > 18, D85 = "Female"), C85 < 0.36), "II", "III")) -> II
A86: 3347 | B86: F | C86: 0.47 | D86: 0.4 | E86: 0.16 | F86: 0.51 | G86: 0.1615 | H86: 0.073 | I86: 0.198 | J86: 14 | K86: 10 | L86: Hazel | M86: Villa | N86: University of Minnesota | O86: 9 | P86: North Pacific | Q86: 1.9 | R86: =IF(OR(AND(J86 > 15, B86 = "Infant"), AND(D86 = "Male", C86 > 0.75), OR(I86 > 0.8, G86 > 0.5), G86 > 1.2), "I", IF(OR(AND(I86 < 0.4, G86 < 0.4), AND(J86 > 15, D86 = "Male"), AND(J86 > 18, D86 = "Female"), C86 < 0.36), "II", "III")) -> II
... A824: 2207 | B824: M | C824: 0.29 | D824: 0.225 | E824: 0.075 | F824: 0.14 | G824: 0.0515 | H824: 0.0235 | I824: 0.04 | J824: 5 | K824: 3 | L824: Inaya | M824: Bernard | N824: Stanford University | O824: 5 | P824: Southeast | Q824: 12.8 | R824: =IF(OR(AND(J824 > 15, B824 = "Infant"), AND(D824 = "Male", C824 > 0.75), OR(I824 > 0.8, G824 > 0.5), G824 > 1.2), "I", IF(OR(AND(I824 < 0.4, G824 < 0.4), AND(J824 > 15, D824 = "Male"), AND(J824 > 18, D824 = "Female"), C824 < 0.36), "II", "III")) -> II
A829: Abalone_id | B829: Gender | C829: Length | D829: Diameter | E829: Height | F829: Whole_weight | G829: Shucked_weight | H829: Viscera_weight | I829: Shell_weight | J829: Rings | K829: Collector | L829: Collector_First | M829: Collector_last | N829: Collector_organization | O829: Water | P829: Water_region | Q829: Feb_temp | R829: Category
A830: 484 | B830: F | C830: 0.58 | D830: 0.46 | E830: 0.15 | F830: 0.9955 | G830: 0.429 | H830: 0.212 | I830: 0.26 | J830: 19 | K830: 10 | L830: Hazel | M830: Villa | N830: University of Minnesota | O830: 9 | P830: North Pacific | Q830: 1.9 | R830: =IF(OR(AND(J830 > 15, B830 = "Infant"), AND(D830 = "Male", C830 > 0.75), OR(I830 > 0.8, G830 > 0.5), G830 > 1.2), "I", IF(OR(AND(I830 < 0.4, G830 < 0.4), AND(J830 > 15, D830 = "Male"), AND(J830 > 18, D830 = "Female"), C830 < 0.36), "II", "III")) -> III
A831: 2948 | B831: F | C831: 0.635 | D831: 0.485 | E831: 0.18 | F831: 1.1795 | G831: 0.4785 | H831: 0.2775 | I831: 0.355 | J831: 10 | K831: 4 | L831: Nate | M831: Craig | N831: NOAA Fisheries | O831: 7 | P831: Great Lakes | Q831: 2.5 | R831: =IF(OR(AND(J831 > 15, B831 = "Infant"), AND(D831 = "Male", C831 > 0.75), OR(I831 > 0.8, G831 > 0.5), G831 > 1.2), "I", IF(OR(AND(I831 < 0.4, G831 < 0.4), AND(J831 > 15, D831 = "Male"), AND(J831 > 18, D831 = "Female"), C831 < 0.36), "II", "III")) -> III
A832: 1480 | B832: F | C832: 0.575 | D832: 0.46 | E832: 0.165 | F832: 0.9155 | G832: 0.4005 | H832: 0.2465 | I832: 0.2385 | J832: 8 | K832: 6 | L832: Martin | M832: Gaines | N832: San Diego State University | O832: 3 | P832: Northeast | Q832: 3.6 | R832: =IF(OR(AND(J832 > 15, B832 = "Infant"), AND(D832 = "Male", C832 > 0.75), OR(I832 > 0.8, G832 > 0.5), G832 > 1.2), "I", IF(OR(AND(I832 < 0.4, G832 < 0.4), AND(J832 > 15, D832 = "Male"), AND(J832 > 18, D832 = "Female"), C832 < 0.36), "II", "III")) -> III
A833: 1000 | B833: F | C833: 0.595 | D833: 0.47 | E833: 0.155 | F833: 1.121 | G833: 0.4515 | H833: 0.178 | I833: 0.155 | J833: 11 | K833: 12 | L833: Rebecca | M833: Bennett | N833: University of Houston | O833: 7 | P833: Great Lakes | Q833: 2.5 | R833: =IF(OR(AND(J833 > 15, B833 = "Infant"), AND(D833 = "Male", C833 > 0.75), OR(I833 > 0.8, G833 > 0.5), G833 > 1.2), "I", IF(OR(AND(I833 < 0.4, G833 < 0.4), AND(J833 > 15, D833 = "Male"), AND(J833 > 18, D833 = "Female"), C833 < 0.36), "II", "III")) -> III
A834: 1483 | B834: F | C834: 0.585 | D834: 0.455 | E834: 0.15 | F834: 0.906 | G834: 0.4095 | H834: 0.23 | I834: 0.2335 | J834: 8 | K834: 15 | L834: Conan | M834: Dalton | N834: University of Houston | O834: 1 | P834: Florida Atlantic Coast | Q834: 22.1 | R834: =IF(OR(AND(J834 > 15, B834 = "Infant"), AND(D834 = "Male", C834 > 0.75), OR(I834 > 0.8, G834 > 0.5), G834 > 1.2), "I", IF(OR(AND(I834 < 0.4, G834 < 0.4), AND(J834 > 15, D834 = "Male"), AND(J834 > 18, D834 = "Female"), C834 < 0.36), "II", "III")) -> III
A835: 3844 | B835: F | C835: 0.575 | D835: 0.45 | E835: 0.16 | F835: 0.955 | G835: 0.44 | H835: 0.1685 | I835: 0.27 | J835: 16 | K835: 3 | L835: Inaya | M835: Bernard | N835: Stanford University | O835: 3 | P835: Northeast | Q835: 3.6 | R835: =IF(OR(AND(J835 > 15, B835 = "Infant"), AND(D835 = "Male", C835 > 0.75), OR(I835 > 0.8, G835 > 0.5), G835 > 1.2), "I", IF(OR(AND(I835 < 0.4, G835 < 0.4), AND(J835 > 15, D835 = "Male"), AND(J835 > 18, D835 = "Female"), C835 < 0.36), "II", "III")) -> III
A836: 4141 | B836: F | C836: 0.645 | D836: 0.535 | E836: 0.19 | F836: 1.2395 | G836: 0.468 | H836: 0.2385 | I836: 0.424 | J836: 10 | K836: 11 | L836: Naima | M836: Reyes | N836: University of Houston | O836: 1 | P836: Florida Atlantic Coast | Q836: 22.1 | R836: =IF(OR(AND(J836 > 15, B836 = "Infant"), AND(D836 = "Male", C836 > 0.75), OR(I836 > 0.8, G836 > 0.5), G836 > 1.2), "I", IF(OR(AND(I836 < 0.4, G836 < 0.4), AND(J836 > 15, D836 = "Male"), AND(J836 > 18, D836 = "Female"), C836 < 0.36), "II", "III")) -> III
A837: 3575 | B837: F | C837: 0.6 | D837: 0.47 | E837: 0.17 | F837: 1.0805 | G837: 0.4995 | H837: 0.2245 | I837: 0.3205 | J837: 9 | K837: 4 | L837: Nate | M837: Craig | N837: NOAA Fisheries | O837: 10 | P837: Pacific | Q837: 24.1 | R837: =IF(OR(AND(J837 > 15, B837 = "Infant"), AND(D837 = "Male", C837 > 0.75), OR(I837 > 0.8, G837 > 0.5), G837 > 1.2), "I", IF(OR(AND(I837 < 0.4, G837 < 0.4), AND(J837 > 15, D837 = "Male"), AND(J837 > 18, D837 = "Female"), C837 < 0.36), "II", "III")) -> III
A838: 1694 | B838: F | C838: 0.625 | D838: 0.485 | E838: 0.15 | F838: 1.044 | G838: 0.438 | H838: 0.2865 | I838: 0.278 | J838: 9 | K838: 8 | L838: Kali | M838: Metcalfe | N838: Mote Marine Laboratory | O838: 4 | P838: Mid-Atlantic | Q838: 6.1 | R838: =IF(OR(AND(J838 > 15, B838 = "Infant"), AND(D838 = "Male", C838 > 0.75), OR(I838 > 0.8, G838 > 0.5), G838 > 1.2), "I", IF(OR(AND(I838 < 0.4, G838 < 0.4), AND(J838 > 15, D838 = "Male"), AND(J838 > 18, D838 = "Female"), C838 < 0.36), "II", "III")) -> III
A839: 1960 | B839: F | C839: 0.65 | D839: 0.51 | E839: 0.155 | F839: 1.189 | G839: 0.483 | H839: 0.278 | I839: 0.3645 | J839: 13 | K839: 10 | L839: Hazel | M839: Villa | N839: University of Minnesota | O839: 1 | P839: Florida Atlantic Coast | Q839: 22.1 | R839: =IF(OR(AND(J839 > 15, B839 = "Infant"), AND(D839 = "Male", C839 > 0.75), OR(I839 > 0.8, G839 > 0.5), G839 > 1.2), "I", IF(OR(AND(I839 < 0.4, G839 < 0.4), AND(J839 > 15, D839 = "Male"), AND(J839 > 18, D839 = "Female"), C839 < 0.36), "II", "III")) -> III
A840: 2210 | B840: F | C840: 0.55 | D840: 0.465 | E840: 0.18 | F840: 1.2125 | G840: 0.3245 | H840: 0.205 | I840: 0.525 | J840: 27 | K840: 15 | L840: Conan | M840: Dalton | N840: University of Houston | O840: 4 | P840: Mid-Atlantic | Q840: 6.1 | R840: =IF(OR(AND(J840 > 15, B840 = "Infant"), AND(D840 = "Male", C840 > 0.75), OR(I840 > 0.8, G840 > 0.5), G840 > 1.2), "I", IF(OR(AND(I840 < 0.4, G840 < 0.4), AND(J840 > 15, D840 = "Male"), AND(J840 > 18, D840 = "Female"), C840 < 0.36), "II", "III")) -> III
...

Sheet Economic Value
A1: Abalone_id | B1: Gender | C1: Length | D1: Diameter | E1: Height | F1: Whole_weight | G1: Shucked_weight | H1: Viscera_weight | I1: Shell_weight | J1: Rings | K1: Collector | L1: Collector_First | M1: Collector_last | N1: Collector_organization | O1: Water | P1: Water_region | Q1: Feb_temp | R1: Category | S1: Economic Value
A2: 2424 | B2: F | C2: 0.41 | D2: 0.315 | E2: 0.11 | F2: 0.321 | G2: 0.1255 | H2: 0.0655 | I2: 0.095 | J2: 10 | K2: 9 | L2: Danica | M2: Tyler | N2: University of Florida | O2: 9 | P2: North Pacific | Q2: 1.9 | R2: =IF(OR(AND(J2 > 15, B2 = "Infant"), AND(D2 = "Male", C2 > 0.75), OR(I2 > 0.8, G2 > 0.5), G2 > 1.2), "I", IF(OR(AND(I2 < 0.4, G2 < 0.4), AND(J2 > 15, D2 = "Male"), AND(J2 > 18, D2 = "Female"), C2 < 0.36), "II", "III")) -> II | S2: =IF(OR(AND(J2 > 15, B2 = "Infant"), AND(D2 = "Male", C2 > 0.75), OR(I2 > 0.8, G2 > 0.5), G2 > 1.2), (1 + (1/3)*(C2 - 0.5) + (1/3)*(D2 - 0.4) + (1/3)*(E2 - 0.4)) * F2 * 0.5 * 1.5, IF(OR(AND(I2 < 0.4, G2 < 0.4), AND(J2 > 15, D2 = "Male"), AND(J2 > 18, D2 = "Female"), C2 < 0.36), (1 + (1/3)*(C2 - 0.5) + (1/3)*(D2 - 0.4) + (1/3)*(E2 - 0.4)) * F2 * 0.5 * 0.8, (1 + (1/3)*(C2 - 0.5) + (1/3)*(D2 - 0.4) + (1/3)*(E2 - 0.4)) * F2 * 0.5)) -> 0.108498 | X2: Avg value
A3: 484 | B3: F | C3: 0.58 | D3: 0.46 | E3: 0.15 | F3: 0.9955 | G3: 0.429 | H3: 0.212 | I3: 0.26 | J3: 19 | K3: 10 | L3: Hazel | M3: Villa | N3: University of Minnesota | O3: 9 | P3: North Pacific | Q3: 1.9 | R3: =IF(OR(AND(J3 > 15, B3 = "Infant"), AND(D3 = "Male", C3 > 0.75), OR(I3 > 0.8, G3 > 0.5), G3 > 1.2), "I", IF(OR(AND(I3 < 0.4, G3 < 0.4), AND(J3 > 15, D3 = "Male"), AND(J3 > 18, D3 = "Female"), C3 < 0.36), "II", "III")) -> III | S3: =IF(OR(AND(J3 > 15, B3 = "Infant"), AND(D3 = "Male", C3 > 0.75), OR(I3 > 0.8, G3 > 0.5), G3 > 1.2), (1 + (1/3)*(C3 - 0.5) + (1/3)*(D3 - 0.4) + (1/3)*(E3 - 0.4)) * F3 * 0.5 * 1.5, IF(OR(AND(I3 < 0.4, G3 < 0.4), AND(J3 > 15, D3 = "Male"), AND(J3 > 18, D3 = "Female"), C3 < 0.36), (1 + (1/3)*(C3 - 0.5) + (1/3)*(D3 - 0.4) + (1/3)*(E3 - 0.4)) * F3 * 0.5 * 0.8, (1 + (1/3)*(C3 - 0.5) + (1/3)*(D3 - 0.4) + (1/3)*(E3 - 0.4)) * F3 * 0.5)) -> 0.47949917 | W3: Gender | X3: Avg value | Y3: MOST EXPENSIVE | Z3: LEAST EXPENSIVE
A4: 2948 | B4: F | C4: 0.635 | D4: 0.485 | E4: 0.18 | F4: 1.1795 | G4: 0.4785 | H4: 0.2775 | I4: 0.355 | J4: 10 | K4: 4 | L4: Nate | M4: Craig | N4: NOAA Fisheries | O4: 7 | P4: Great Lakes | Q4: 2.5 | R4: =IF(OR(AND(J4 > 15, B4 = "Infant"), AND(D4 = "Male", C4 > 0.75), OR(I4 > 0.8, G4 > 0.5), G4 > 1.2), "I", IF(OR(AND(I4 < 0.4, G4 < 0.4), AND(J4 > 15, D4 = "Male"), AND(J4 > 18, D4 = "Female"), C4 < 0.36), "II", "III")) -> III | S4: =IF(OR(AND(J4 > 15, B4 = "Infant"), AND(D4 = "Male", C4 > 0.75), OR(I4 > 0.8, G4 > 0.5), G4 > 1.2), (1 + (1/3)*(C4 - 0.5) + (1/3)*(D4 - 0.4) + (1/3)*(E4 - 0.4)) * F4 * 0.5 * 1.5, IF(OR(AND(I4 < 0.4, G4 < 0.4), AND(J4 > 15, D4 = "Male"), AND(J4 > 18, D4 = "Female"), C4 < 0.36), (1 + (1/3)*(C4 - 0.5) + (1/3)*(D4 - 0.4) + (1/3)*(E4 - 0.4)) * F4 * 0.5 * 0.8, (1 + (1/3)*(C4 - 0.5) + (1/3)*(D4 - 0.4) + (1/3)*(E4 - 0.4)) * F4 * 0.5)) -> 0.58975 | W4: M | X4: =AVERAGEIF(B:B, "M", S:S) -> 0.29902257 | Y4: =_xlfn.MAXIFS(S:S, B:B, "M") -> 0.93469 | Z4: =_xlfn.MINIFS(S:S, B:B, "M") -> 0.0033973333
A5: 2404 | B5: F | C5: 0.29 | D5: 0.225 | E5: 0.08 | F5: 0.1295 | G5: 0.0535 | H5: 0.026 | I5: 0.045 | J5: 10 | K5: 13 | L5: Betty | M5: Berg | N5: University of Houston | O5: 8 | P5: West Coast | Q5: 12.3 | R5: =IF(OR(AND(J5 > 15, B5 = "Infant"), AND(D5 = "Male", C5 > 0.75), OR(I5 > 0.8, G5 > 0.5), G5 > 1.2), "I", IF(OR(AND(I5 < 0.4, G5 < 0.4), AND(J5 > 15, D5 = "Male"), AND(J5 > 18, D5 = "Female"), C5 < 0.36), "II", "III")) -> II | S5: =IF(OR(AND(J5 > 15, B5 = "Infant"), AND(D5 = "Male", C5 > 0.75), OR(I5 > 0.8, G5 > 0.5), G5 > 1.2), (1 + (1/3)*(C5 - 0.5) + (1/3)*(D5 - 0.4) + (1/3)*(E5 - 0.4)) * F5 * 0.5 * 1.5, IF(OR(AND(I5 < 0.4, G5 < 0.4), AND(J5 > 15, D5 = "Male"), AND(J5 > 18, D5 = "Female"), C5 < 0.36), (1 + (1/3)*(C5 - 0.5) + (1/3)*(D5 - 0.4) + (1/3)*(E5 - 0.4)) * F5 * 0.5 * 0.8, (1 + (1/3)*(C5 - 0.5) + (1/3)*(D5 - 0.4) + (1/3)*(E5 - 0.4)) * F5 * 0.5)) -> 0.039627 | W5: F | X5: =AVERAGEIF(B:B, "F", S:S) -> 0.28832012 | Y5: =_xlfn.MAXIFS(S:S, B:B, "F") -> 0.94088 | Z5: =_xlfn.MINIFS(S:S, B:B, "F") -> 0.0064233333
A6: 1480 | B6: F | C6: 0.575 | D6: 0.46 | E6: 0.165 | F6: 0.9155 | G6: 0.4005 | H6: 0.2465 | I6: 0.2385 | J6: 8 | K6: 6 | L6: Martin | M6: Gaines | N6: San Diego State University | O6: 3 | P6: Northeast | Q6: 3.6 | R6: =IF(OR(AND(J6 > 15, B6 = "Infant"), AND(D6 = "Male", C6 > 0.75), OR(I6 > 0.8, G6 > 0.5), G6 > 1.2), "I", IF(OR(AND(I6 < 0.4, G6 < 0.4), AND(J6 > 15, D6 = "Male"), AND(J6 > 18, D6 = "Female"), C6 < 0.36), "II", "III")) -> III | S6: =IF(OR(AND(J6 > 15, B6 = "Infant"), AND(D6 = "Male", C6 > 0.75), OR(I6 > 0.8, G6 > 0.5), G6 > 1.2), (1 + (1/3)*(C6 - 0.5) + (1/3)*(D6 - 0.4) + (1/3)*(E6 - 0.4)) * F6 * 0.5 * 1.5, IF(OR(AND(I6 < 0.4, G6 < 0.4), AND(J6 > 15, D6 = "Male"), AND(J6 > 18, D6 = "Female"), C6 < 0.36), (1 + (1/3)*(C6 - 0.5) + (1/3)*(D6 - 0.4) + (1/3)*(E6 - 0.4)) * F6 * 0.5 * 0.8, (1 + (1/3)*(C6 - 0.5) + (1/3)*(D6 - 0.4) + (1/3)*(E6 - 0.4)) * F6 * 0.5)) -> 0.44249167 | W6: I | X6: =AVERAGEIF(B:B, "I", S:S) -> 0.27492943 | Y6: =_xlfn.MAXIFS(S:S, B:B, "I") -> 0.92816938 | Z6: =_xlfn.MINIFS(S:S, B:B, "I") -> 0.0020586667
A7: 1150 | B7: F | C7: 0.58 | D7: 0.45 | E7: 0.155 | F7: 0.93 | G7: 0.385 | H7: 0.246 | I7: 0.265 | J7: 9 | K7: 2 | L7: Tiegan | M7: Davie | N7: University of California, Davis | O7: 2 | P7: Florida Gulf Coast | Q7: 18 | R7: =IF(OR(AND(J7 > 15, B7 = "Infant"), AND(D7 = "Male", C7 > 0.75), OR(I7 > 0.8, G7 > 0.5), G7 > 1.2), "I", IF(OR(AND(I7 < 0.4, G7 < 0.4), AND(J7 > 15, D7 = "Male"), AND(J7 > 18, D7 = "Female"), C7 < 0.36), "II", "III")) -> II | S7: =IF(OR(AND(J7 > 15, B7 = "Infant"), AND(D7 = "Male", C7 > 0.75), OR(I7 > 0.8, G7 > 0.5), G7 > 1.2), (1 + (1/3)*(C7 - 0.5) + (1/3)*(D7 - 0.4) + (1/3)*(E7 - 0.4)) * F7 * 0.5 * 1.5, IF(OR(AND(I7 < 0.4, G7 < 0.4), AND(J7 > 15, D7 = "Male"), AND(J7 > 18, D7 = "Female"), C7 < 0.36), (1 + (1/3)*(C7 - 0.5) + (1/3)*(D7 - 0.4) + (1/3)*(E7 - 0.4)) * F7 * 0.5 * 0.8, (1 + (1/3)*(C7 - 0.5) + (1/3)*(D7 - 0.4) + (1/3)*(E7 - 0.4)) * F7 * 0.5)) -> 0.35774
A8: 1319 | B8: F | C8: 0.555 | D8: 0.43 | E8: 0.14 | F8: 0.7665 | G8: 0.341 | H8: 0.165 | I8: 0.23 | J8: 9 | K8: 3 | L8: Inaya | M8: Bernard | N8: Stanford University | O8: 3 | P8: Northeast | Q8: 3.6 | R8: =IF(OR(AND(J8 > 15, B8 = "Infant"), AND(D8 = "Male", C8 > 0.75), OR(I8 > 0.8, G8 > 0.5), G8 > 1.2), "I", IF(OR(AND(I8 < 0.4, G8 < 0.4), AND(J8 > 15, D8 = "Male"), AND(J8 > 18, D8 = "Female"), C8 < 0.36), "II", "III")) -> II | S8: =IF(OR(AND(J8 > 15, B8 = "Infant"), AND(D8 = "Male", C8 > 0.75), OR(I8 > 0.8, G8 > 0.5), G8 > 1.2), (1 + (1/3)*(C8 - 0.5) + (1/3)*(D8 - 0.4) + (1/3)*(E8 - 0.4)) * F8 * 0.5 * 1.5, IF(OR(AND(I8 < 0.4, G8 < 0.4), AND(J8 > 15, D8 = "Male"), AND(J8 > 18, D8 = "Female"), C8 < 0.36), (1 + (1/3)*(C8 - 0.5) + (1/3)*(D8 - 0.4) + (1/3)*(E8 - 0.4)) * F8 * 0.5 * 0.8, (1 + (1/3)*(C8 - 0.5) + (1/3)*(D8 - 0.4) + (1/3)*(E8 - 0.4)) * F8 * 0.5)) -> 0.288715
A9: 2110 | B9: F | C9: 0.62 | D9: 0.49 | E9: 0.17 | F9: 1.2105 | G9: 0.5185 | H9: 0.2555 | I9: 0.335 | J9: 13 | K9: 8 | L9: Kali | M9: Metcalfe | N9: Mote Marine Laboratory | O9: 8 | P9: West Coast | Q9: 12.3 | R9: =IF(OR(AND(J9 > 15, B9 = "Infant"), AND(D9 = "Male", C9 > 0.75), OR(I9 > 0.8, G9 > 0.5), G9 > 1.2), "I", IF(OR(AND(I9 < 0.4, G9 < 0.4), AND(J9 > 15, D9 = "Male"), AND(J9 > 18, D9 = "Female"), C9 < 0.36), "II", "III")) -> I | S9: =IF(OR(AND(J9 > 15, B9 = "Infant"), AND(D9 = "Male", C9 > 0.75), OR(I9 > 0.8, G9 > 0.5), G9 > 1.2), (1 + (1/3)*(C9 - 0.5) + (1/3)*(D9 - 0.4) + (1/3)*(E9 - 0.4)) * F9 * 0.5 * 1.5, IF(OR(AND(I9 < 0.4, G9 < 0.4), AND(J9 > 15, D9 = "Male"), AND(J9 > 18, D9 = "Female"), C9 < 0.36), (1 + (1/3)*(C9 - 0.5) + (1/3)*(D9 - 0.4) + (1/3)*(E9 - 0.4)) * F9 * 0.5 * 0.8, (1 + (1/3)*(C9 - 0.5) + (1/3)*(D9 - 0.4) + (1/3)*(E9 - 0.4)) * F9 * 0.5)) -> 0.9018225
A10: 1000 | B10: F | C10: 0.595 | D10: 0.47 | E10: 0.155 | F10: 1.121 | G10: 0.4515 | H10: 0.178 | I10: 0.155 | J10: 11 | K10: 12 | L10: Rebecca | M10: Bennett | N10: University of Houston | O10: 7 | P10: Great Lakes | Q10: 2.5 | R10: =IF(OR(AND(J10 > 15, B10 = "Infant"), AND(D10 = "Male", C10 > 0.75), OR(I10 > 0.8, G10 > 0.5), G10 > 1.2), "I", IF(OR(AND(I10 < 0.4, G10 < 0.4), AND(J10 > 15, D10 = "Male"), AND(J10 > 18, D10 = "Female"), C10 < 0.36), "II", "III")) -> III | S10: =IF(OR(AND(J10 > 15, B10 = "Infant"), AND(D10 = "Male", C10 > 0.75), OR(I10 > 0.8, G10 > 0.5), G10 > 1.2), (1 + (1/3)*(C10 - 0.5) + (1/3)*(D10 - 0.4) + (1/3)*(E10 - 0.4)) * F10 * 0.5 * 1.5, IF(OR(AND(I10 < 0.4, G10 < 0.4), AND(J10 > 15, D10 = "Male"), AND(J10 > 18, D10 = "Female"), C10 < 0.36), (1 + (1/3)*(C10 - 0.5) + (1/3)*(D10 - 0.4) + (1/3)*(E10 - 0.4)) * F10 * 0.5 * 0.8, (1 + (1/3)*(C10 - 0.5) + (1/3)*(D10 - 0.4) + (1/3)*(E10 - 0.4)) * F10 * 0.5)) -> 0.54555333 | W10: Water Region | X10: Avg value | Y10: Most Expensive | Z10: Least Expensive
A11: 228 | B11: F | C11: 0.365 | D11: 0.27 | E11: 0.085 | F11: 0.205 | G11: 0.078 | H11: 0.0485 | I11: 0.07 | J11: 7 | K11: 2 | L11: Tiegan | M11: Davie | N11: University of California, Davis | O11: 4 | P11: Mid-Atlantic | Q11: 6.1 | R11: =IF(OR(AND(J11 > 15, B11 = "Infant"), AND(D11 = "Male", C11 > 0.75), OR(I11 > 0.8, G11 > 0.5), G11 > 1.2), "I", IF(OR(AND(I11 < 0.4, G11 < 0.4), AND(J11 > 15, D11 = "Male"), AND(J11 > 18, D11 = "Female"), C11 < 0.36), "II", "III")) -> II | S11: =IF(OR(AND(J11 > 15, B11 = "Infant"), AND(D11 = "Male", C11 > 0.75), OR(I11 > 0.8, G11 > 0.5), G11 > 1.2), (1 + (1/3)*(C11 - 0.5) + (1/3)*(D11 - 0.4) + (1/3)*(E11 - 0.4)) * F11 * 0.5 * 1.5, IF(OR(AND(I11 < 0.4, G11 < 0.4), AND(J11 > 15, D11 = "Male"), AND(J11 > 18, D11 = "Female"), C11 < 0.36), (1 + (1/3)*(C11 - 0.5) + (1/3)*(D11 - 0.4) + (1/3)*(E11 - 0.4)) * F11 * 0.5 * 0.8, (1 + (1/3)*(C11 - 0.5) + (1/3)*(D11 - 0.4) + (1/3)*(E11 - 0.4)) * F11 * 0.5)) -> 0.066146667 | W11: Great Lakes | X11: =AVERAGEIF(P:P, "Great Lakes", S:S) -> 0.31894428 | Y11: =_xlfn.MAXIFS(S:S, P:P, "Great Lakes") -> 0.92802125 | Z11: =_xlfn.MINIFS(S:S, P:P, "Great Lakes") -> 0.005642
A12: 3945 | B12: F | C12: 0.55 | D12: 0.44 | E12: 0.16 | F12: 0.991 | G12: 0.348 | H12: 0.168 | I12: 0.375 | J12: 20 | K12: 8 | L12: Kali | M12: Metcalfe | N12: Mote Marine Laboratory | O12: 1 | P12: Florida Atlantic Coast | Q12: 22.1 | R12: =IF(OR(AND(J12 > 15, B12 = "Infant"), AND(D12 = "Male", C12 > 0.75), OR(I12 > 0.8, G12 > 0.5), G12 > 1.2), "I", IF(OR(AND(I12 < 0.4, G12 < 0.4), AND(J12 > 15, D12 = "Male"), AND(J12 > 18, D12 = "Female"), C12 < 0.36), "II", "III")) -> II | S12: =IF(OR(AND(J12 > 15, B12 = "Infant"), AND(D12 = "Male", C12 > 0.75), OR(I12 > 0.8, G12 > 0.5), G12 > 1.2), (1 + (1/3)*(C12 - 0.5) + (1/3)*(D12 - 0.4) + (1/3)*(E12 - 0.4)) * F12 * 0.5 * 1.5, IF(OR(AND(I12 < 0.4, G12 < 0.4), AND(J12 > 15, D12 = "Male"), AND(J12 > 18, D12 = "Female"), C12 < 0.36), (1 + (1/3)*(C12 - 0.5) + (1/3)*(D12 - 0.4) + (1/3)*(E12 - 0.4)) * F12 * 0.5 * 0.8, (1 + (1/3)*(C12 - 0.5) + (1/3)*(D12 - 0.4) + (1/3)*(E12 - 0.4)) * F12 * 0.5)) -> 0.37658 | W12: North East | X12: =AVERAGEIF(P:P, "Northeast", S:S) -> 0.28218259 | Y12: =_xlfn.MAXIFS(S:S, P:P, "Northeast") -> 0.94088 | Z12: =_xlfn.MINIFS(S:S, P:P, "Northeast") -> 0.005187
A13: 1308 | B13: F | C13: 0.545 | D13: 0.435 | E13: 0.135 | F13: 0.7715 | G13: 0.372 | H13: 0.148 | I13: 0.227 | J13: 8 | K13: 12 | L13: Rebecca | M13: Bennett | N13: University of Houston | O13: 5 | P13: Southeast | Q13: 12.8 | R13: =IF(OR(AND(J13 > 15, B13 = "Infant"), AND(D13 = "Male", C13 > 0.75), OR(I13 > 0.8, G13 > 0.5), G13 > 1.2), "I", IF(OR(AND(I13 < 0.4, G13 < 0.4), AND(J13 > 15, D13 = "Male"), AND(J13 > 18, D13 = "Female"), C13 < 0.36), "II", "III")) -> II | S13: =IF(OR(AND(J13 > 15, B13 = "Infant"), AND(D13 = "Male", C13 > 0.75), OR(I13 > 0.8, G13 > 0.5), G13 > 1.2), (1 + (1/3)*(C13 - 0.5) + (1/3)*(D13 - 0.4) + (1/3)*(E13 - 0.4)) * F13 * 0.5 * 1.5, IF(OR(AND(I13 < 0.4, G13 < 0.4), AND(J13 > 15, D13 = "Male"), AND(J13 > 18, D13 = "Female"), C13 < 0.36), (1 + (1/3)*(C13 - 0.5) + (1/3)*(D13 - 0.4) + (1/3)*(E13 - 0.4)) * F13 * 0.5 * 0.8, (1 + (1/3)*(C13 - 0.5) + (1/3)*(D13 - 0.4) + (1/3)*(E13 - 0.4)) * F13 * 0.5)) -> 0.28956967 | W13: Pacific | X13: =AVERAGEIF(P:P, "Pacific", S:S) -> 0.30518237 | Y13: =_xlfn.MAXIFS(S:S, P:P, "Pacific") -> 0.91331812 | Z13: =_xlfn.MINIFS(S:S, P:P, "Pacific") -> 0.0041436667
A14: 2895 | B14: F | C14: 0.54 | D14: 0.425 | E14: 0.13 | F14: 0.8155 | G14: 0.3675 | H14: 0.1365 | I14: 0.246 | J14: 11 | K14: 8 | L14: Kali | M14: Metcalfe | N14: Mote Marine Laboratory | O14: 4 | P14: Mid-Atlantic | Q14: 6.1 | R14: =IF(OR(AND(J14 > 15, B14 = "Infant"), AND(D14 = "Male", C14 > 0.75), OR(I14 > 0.8, G14 > 0.5), G14 > 1.2), "I", IF(OR(AND(I14 < 0.4, G14 < 0.4), AND(J14 > 15, D14 = "Male"), AND(J14 > 18, D14 = "Female"), C14 < 0.36), "II", "III")) -> II | S14: =IF(OR(AND(J14 > 15, B14 = "Infant"), AND(D14 = "Male", C14 > 0.75), OR(I14 > 0.8, G14 > 0.5), G14 > 1.2), (1 + (1/3)*(C14 - 0.5) + (1/3)*(D14 - 0.4) + (1/3)*(E14 - 0.4)) * F14 * 0.5 * 1.5, IF(OR(AND(I14 < 0.4, G14 < 0.4), AND(J14 > 15, D14 = "Male"), AND(J14 > 18, D14 = "Female"), C14 < 0.36), (1 + (1/3)*(C14 - 0.5) + (1/3)*(D14 - 0.4) + (1/3)*(E14 - 0.4)) * F14 * 0.5 * 0.8, (1 + (1/3)*(C14 - 0.5) + (1/3)*(D14 - 0.4) + (1/3)*(E14 - 0.4)) * F14 * 0.5)) -> 0.30390967 | W14: Florida Atlantic Coast | X14: =AVERAGEIF(P:P, "Florida Atlantic Coast", S:S) -> 0.29686699 | Y14: =_xlfn.MAXIFS(S:S, P:P, "Florida Atlantic Coast") -> 0.92816938 | Z14: =_xlfn.MINIFS(S:S, P:P, "Florida Atlantic Coast") -> 0.010384667
A15: 1483 | B15: F | C15: 0.585 | D15: 0.455 | E15: 0.15 | F15: 0.906 | G15: 0.4095 | H15: 0.23 | I15: 0.2335 | J15: 8 | K15: 15 | L15: Conan | M15: Dalton | N15: University of Houston | O15: 1 | P15: Florida Atlantic Coast | Q15: 22.1 | R15: =IF(OR(AND(J15 > 15, B15 = "Infant"), AND(D15 = "Male", C15 > 0.75), OR(I15 > 0.8, G15 > 0.5), G15 > 1.2), "I", IF(OR(AND(I15 < 0.4, G15 < 0.4), AND(J15 > 15, D15 = "Male"), AND(J15 > 18, D15 = "Female"), C15 < 0.36), "II", "III")) -> III | S15: =IF(OR(AND(J15 > 15, B15 = "Infant"), AND(D15 = "Male", C15 > 0.75), OR(I15 > 0.8, G15 > 0.5), G15 > 1.2), (1 + (1/3)*(C15 - 0.5) + (1/3)*(D15 - 0.4) + (1/3)*(E15 - 0.4)) * F15 * 0.5 * 1.5, IF(OR(AND(I15 < 0.4, G15 < 0.4), AND(J15 > 15, D15 = "Male"), AND(J15 > 18, D15 = "Female"), C15 < 0.36), (1 + (1/3)*(C15 - 0.5) + (1/3)*(D15 - 0.4) + (1/3)*(E15 - 0.4)) * F15 * 0.5 * 0.8, (1 + (1/3)*(C15 - 0.5) + (1/3)*(D15 - 0.4) + (1/3)*(E15 - 0.4)) * F15 * 0.5)) -> 0.43639 | W15: Mid-Atlantic | X15: =AVERAGEIF(P:P, "Mid-Atlantic", S:S) -> 0.28590318 | Y15: =_xlfn.MAXIFS(S:S, P:P, "Mid-Atlantic") -> 0.92635875 | Z15: =_xlfn.MINIFS(S:S, P:P, "Mid-Atlantic") -> 0.016874
A16: 3411 | B16: F | C16: 0.415 | D16: 0.31 | E16: 0.105 | F16: 0.3595 | G16: 0.167 | H16: 0.083 | I16: 0.0915 | J16: 6 | K16: 7 | L16: Iona | M16: Connolly | N16: Florida Atlantic University | O16: 9 | P16: North Pacific | Q16: 1.9 | R16: =IF(OR(AND(J16 > 15, B16 = "Infant"), AND(D16 = "Male", C16 > 0.75), OR(I16 > 0.8, G16 > 0.5), G16 > 1.2), "I", IF(OR(AND(I16 < 0.4, G16 < 0.4), AND(J16 > 15, D16 = "Male"), AND(J16 > 18, D16 = "Female"), C16 < 0.36), "II", "III")) -> II | S16: =IF(OR(AND(J16 > 15, B16 = "Infant"), AND(D16 = "Male", C16 > 0.75), OR(I16 > 0.8, G16 > 0.5), G16 > 1.2), (1 + (1/3)*(C16 - 0.5) + (1/3)*(D16 - 0.4) + (1/3)*(E16 - 0.4)) * F16 * 0.5 * 1.5, IF(OR(AND(I16 < 0.4, G16 < 0.4), AND(J16 > 15, D16 = "Male"), AND(J16 > 18, D16 = "Female"), C16 < 0.36), (1 + (1/3)*(C16 - 0.5) + (1/3)*(D16 - 0.4) + (1/3)*(E16 - 0.4)) * F16 * 0.5 * 0.8, (1 + (1/3)*(C16 - 0.5) + (1/3)*(D16 - 0.4) + (1/3)*(E16 - 0.4)) * F16 * 0.5)) -> 0.12127133 | W16: West Coast | X16: =AVERAGEIF(P:P, "West Coast", S:S) -> 0.27080617 | Y16: =_xlfn.MAXIFS(S:S, P:P, "West Coast") -> 0.9018225 | Z16: =_xlfn.MINIFS(S:S, P:P, "West Coast") -> 0.0064233333
A17: 2764 | B17: F | C17: 0.55 | D17: 0.425 | E17: 0.135 | F17: 0.656 | G17: 0.257 | H17: 0.17 | I17: 0.203 | J17: 10 | K17: 11 | L17: Naima | M17: Reyes | N17: University of Houston | O17: 1 | P17: Florida Atlantic Coast | Q17: 22.1 | R17: =IF(OR(AND(J17 > 15, B17 = "Infant"), AND(D17 = "Male", C17 > 0.75), OR(I17 > 0.8, G17 > 0.5), G17 > 1.2), "I", IF(OR(AND(I17 < 0.4, G17 < 0.4), AND(J17 > 15, D17 = "Male"), AND(J17 > 18, D17 = "Female"), C17 < 0.36), "II", "III")) -> II | S17: =IF(OR(AND(J17 > 15, B17 = "Infant"), AND(D17 = "Male", C17 > 0.75), OR(I17 > 0.8, G17 > 0.5), G17 > 1.2), (1 + (1/3)*(C17 - 0.5) + (1/3)*(D17 - 0.4) + (1/3)*(E17 - 0.4)) * F17 * 0.5 * 1.5, IF(OR(AND(I17 < 0.4, G17 < 0.4), AND(J17 > 15, D17 = "Male"), AND(J17 > 18, D17 = "Female"), C17 < 0.36), (1 + (1/3)*(C17 - 0.5) + (1/3)*(D17 - 0.4) + (1/3)*(E17 - 0.4)) * F17 * 0.5 * 0.8, (1 + (1/3)*(C17 - 0.5) + (1/3)*(D17 - 0.4) + (1/3)*(E17 - 0.4)) * F17 * 0.5)) -> 0.24578133 | W17: North Pacific | X17: =AVERAGEIF(P:P, "North Pacific", S:S) -> 0.30460749 | Y17: =_xlfn.MAXIFS(S:S, P:P, "North Pacific") -> 0.9100175 | Z17: =_xlfn.MINIFS(S:S, P:P, "North Pacific") -> 0.017262667
A18: 3342 | B18: F | C18: 0.49 | D18: 0.39 | E18: 0.135 | F18: 0.59 | G18: 0.215 | H18: 0.125 | I18: 0.1845 | J18: 12 | K18: 3 | L18: Inaya | M18: Bernard | N18: Stanford University | O18: 6 | P18: Gulf of Mexico | Q18: 14.1 | R18: =IF(OR(AND(J18 > 15, B18 = "Infant"), AND(D18 = "Male", C18 > 0.75), OR(I18 > 0.8, G18 > 0.5), G18 > 1.2), "I", IF(OR(AND(I18 < 0.4, G18 < 0.4), AND(J18 > 15, D18 = "Male"), AND(J18 > 18, D18 = "Female"), C18 < 0.36), "II", "III")) -> II | S18: =IF(OR(AND(J18 > 15, B18 = "Infant"), AND(D18 = "Male", C18 > 0.75), OR(I18 > 0.8, G18 > 0.5), G18 > 1.2), (1 + (1/3)*(C18 - 0.5) + (1/3)*(D18 - 0.4) + (1/3)*(E18 - 0.4)) * F18 * 0.5 * 1.5, IF(OR(AND(I18 < 0.4, G18 < 0.4), AND(J18 > 15, D18 = "Male"), AND(J18 > 18, D18 = "Female"), C18 < 0.36), (1 + (1/3)*(C18 - 0.5) + (1/3)*(D18 - 0.4) + (1/3)*(E18 - 0.4)) * F18 * 0.5 * 0.8, (1 + (1/3)*(C18 - 0.5) + (1/3)*(D18 - 0.4) + (1/3)*(E18 - 0.4)) * F18 * 0.5)) -> 0.21358 | W18: Southeast | X18: =AVERAGEIF(P:P, "Southeast", S:S) -> 0.25856821 | Y18: =_xlfn.MAXIFS(S:S, P:P, "Southeast") -> 0.93469 | Z18: =_xlfn.MINIFS(S:S, P:P, "Southeast") -> 0.003828
A19: 3347 | B19: F | C19: 0.47 | D19: 0.4 | E19: 0.16 | F19: 0.51 | G19: 0.1615 | H19: 0.073 | I19: 0.198 | J19: 14 | K19: 10 | L19: Hazel | M19: Villa | N19: University of Minnesota | O19: 9 | P19: North Pacific | Q19: 1.9 | R19: =IF(OR(AND(J19 > 15, B19 = "Infant"), AND(D19 = "Male", C19 > 0.75), OR(I19 > 0.8, G19 > 0.5), G19 > 1.2), "I", IF(OR(AND(I19 < 0.4, G19 < 0.4), AND(J19 > 15, D19 = "Male"), AND(J19 > 18, D19 = "Female"), C19 < 0.36), "II", "III")) -> II | S19: =IF(OR(AND(J19 > 15, B19 = "Infant"), AND(D19 = "Male", C19 > 0.75), OR(I19 > 0.8, G19 > 0.5), G19 > 1.2), (1 + (1/3)*(C19 - 0.5) + (1/3)*(D19 - 0.4) + (1/3)*(E19 - 0.4)) * F19 * 0.5 * 1.5, IF(OR(AND(I19 < 0.4, G19 < 0.4), AND(J19 > 15, D19 = "Male"), AND(J19 > 18, D19 = "Female"), C19 < 0.36), (1 + (1/3)*(C19 - 0.5) + (1/3)*(D19 - 0.4) + (1/3)*(E19 - 0.4)) * F19 * 0.5 * 0.8, (1 + (1/3)*(C19 - 0.5) + (1/3)*(D19 - 0.4) + (1/3)*(E19 - 0.4)) * F19 * 0.5)) -> 0.18564 | W19: Florida Gulf Coast | X19: =AVERAGEIF(P:P, "Florida Gulf Coast", S:S) -> 0.25577131 | Y19: =_xlfn.MAXIFS(S:S, P:P, "Florida Gulf Coast") -> 0.9288275 | Z19: =_xlfn.MINIFS(S:S, P:P, "Florida Gulf Coast") -> 0.007616
A20: 1855 | B20: F | C20: 0.495 | D20: 0.375 | E20: 0.14 | F20: 0.494 | G20: 0.181 | H20: 0.0975 | I20: 0.191 | J20: 8 | K20: 2 | L20: Tiegan | M20: Davie | N20: University of California, Davis | O20: 6 | P20: Gulf of Mexico | Q20: 14.1 | R20: =IF(OR(AND(J20 > 15, B20 = "Infant"), AND(D20 = "Male", C20 > 0.75), OR(I20 > 0.8, G20 > 0.5), G20 > 1.2), "I", IF(OR(AND(I20 < 0.4, G20 < 0.4), AND(J20 > 15, D20 = "Male"), AND(J20 > 18, D20 = "Female"), C20 < 0.36), "II", "III")) -> II | S20: =IF(OR(AND(J20 > 15, B20 = "Infant"), AND(D20 = "Male", C20 > 0.75), OR(I20 > 0.8, G20 > 0.5), G20 > 1.2), (1 + (1/3)*(C20 - 0.5) + (1/3)*(D20 - 0.4) + (1/3)*(E20 - 0.4)) * F20 * 0.5 * 1.5, IF(OR(AND(I20 < 0.4, G20 < 0.4), AND(J20 > 15, D20 = "Male"), AND(J20 > 18, D20 = "Female"), C20 < 0.36), (1 + (1/3)*(C20 - 0.5) + (1/3)*(D20 - 0.4) + (1/3)*(E20 - 0.4)) * F20 * 0.5 * 0.8, (1 + (1/3)*(C20 - 0.5) + (1/3)*(D20 - 0.4) + (1/3)*(E20 - 0.4)) * F20 * 0.5)) -> 0.17849867 | W20: Gulf of Mexico | X20: 0.987878 | Y20: =_xlfn.MAXIFS(S:S, P:P, "Great Lakes") -> 0.92802125 | Z20: =_xlfn.MINIFS(S:S, P:P, "Great Lakes") -> 0.005642
A21: 3194 | B21: F | C21: 0.565 | D21: 0.435 | E21: 0.185 | F21: 1.032 | G21: 0.354 | H21: 0.2045 | I21: 0.31 | J21: 20 | K21: 5 | L21: Haniya | M21: Talley | N21: Prince William Sound Science Center | O21: 9 | P21: North Pacific | Q21: 1.9 | R21: =IF(OR(AND(J21 > 15, B21 = "Infant"), AND(D21 = "Male", C21 > 0.75), OR(I21 > 0.8, G21 > 0.5), G21 > 1.2), "I", IF(OR(AND(I21 < 0.4, G21 < 0.4), AND(J21 > 15, D21 = "Male"), AND(J21 > 18, D21 = "Female"), C21 < 0.36), "II", "III")) -> II | S21: =IF(OR(AND(J21 > 15, B21 = "Infant"), AND(D21 = "Male", C21 > 0.75), OR(I21 > 0.8, G21 > 0.5), G21 > 1.2), (1 + (1/3)*(C21 - 0.5) + (1/3)*(D21 - 0.4) + (1/3)*(E21 - 0.4)) * F21 * 0.5 * 1.5, IF(OR(AND(I21 < 0.4, G21 < 0.4), AND(J21 > 15, D21 = "Male"), AND(J21 > 18, D21 = "Female"), C21 < 0.36), (1 + (1/3)*(C21 - 0.5) + (1/3)*(D21 - 0.4) + (1/3)*(E21 - 0.4)) * F21 * 0.5 * 0.8, (1 + (1/3)*(C21 - 0.5) + (1/3)*(D21 - 0.4) + (1/3)*(E21 - 0.4)) * F21 * 0.5)) -> 0.396976
A22: 628 | B22: F | C22: 0.38 | D22: 0.305 | E22: 0.095 | F22: 0.2815 | G22: 0.1255 | H22: 0.0525 | I22: 0.09 | J22: 8 | K22: 15 | L22: Conan | M22: Dalton | N22: University of Houston | O22: 10 | P22: Pacific | Q22: 24.1 | R22: =IF(OR(AND(J22 > 15, B22 = "Infant"), AND(D22 = "Male", C22 > 0.75), OR(I22 > 0.8, G22 > 0.5), G22 > 1.2), "I", IF(OR(AND(I22 < 0.4, G22 < 0.4), AND(J22 > 15, D22 = "Male"), AND(J22 > 18, D22 = "Female"), C22 < 0.36), "II", "III")) -> II | S22: =IF(OR(AND(J22 > 15, B22 = "Infant"), AND(D22 = "Male", C22 > 0.75), OR(I22 > 0.8, G22 > 0.5), G22 > 1.2), (1 + (1/3)*(C22 - 0.5) + (1/3)*(D22 - 0.4) + (1/3)*(E22 - 0.4)) * F22 * 0.5 * 1.5, IF(OR(AND(I22 < 0.4, G22 < 0.4), AND(J22 > 15, D22 = "Male"), AND(J22 > 18, D22 = "Female"), C22 < 0.36), (1 + (1/3)*(C22 - 0.5) + (1/3)*(D22 - 0.4) + (1/3)*(E22 - 0.4)) * F22 * 0.5 * 0.8, (1 + (1/3)*(C22 - 0.5) + (1/3)*(D22 - 0.4) + (1/3)*(E22 - 0.4)) * F22 * 0.5)) -> 0.093082667
A23: 1671 | B23: F | C23: 0.61 | D23: 0.485 | E23: 0.15 | F23: 1.2405 | G23: 0.6025 | H23: 0.2915 | I23: 0.3085 | J23: 12 | K23: 13 | L23: Betty | M23: Berg | N23: University of Houston | O23: 10 | P23: Pacific | Q23: 24.1 | R23: =IF(OR(AND(J23 > 15, B23 = "Infant"), AND(D23 = "Male", C23 > 0.75), OR(I23 > 0.8, G23 > 0.5), G23 > 1.2), "I", IF(OR(AND(I23 < 0.4, G23 < 0.4), AND(J23 > 15, D23 = "Male"), AND(J23 > 18, D23 = "Female"), C23 < 0.36), "II", "III")) -> I | S23: =IF(OR(AND(J23 > 15, B23 = "Infant"), AND(D23 = "Male", C23 > 0.75), OR(I23 > 0.8, G23 > 0.5), G23 > 1.2), (1 + (1/3)*(C23 - 0.5) + (1/3)*(D23 - 0.4) + (1/3)*(E23 - 0.4)) * F23 * 0.5 * 1.5, IF(OR(AND(I23 < 0.4, G23 < 0.4), AND(J23 > 15, D23 = "Male"), AND(J23 > 18, D23 = "Female"), C23 < 0.36), (1 + (1/3)*(C23 - 0.5) + (1/3)*(D23 - 0.4) + (1/3)*(E23 - 0.4)) * F23 * 0.5 * 0.8, (1 + (1/3)*(C23 - 0.5) + (1/3)*(D23 - 0.4) + (1/3)*(E23 - 0.4)) * F23 * 0.5)) -> 0.91331812
A24: 387 | B24: F | C24: 0.54 | D24: 0.42 | E24: 0.155 | F24: 0.7385 | G24: 0.3515 | H24: 0.152 | I24: 0.215 | J24: 12 | K24: 1 | L24: Jan | M24: Odom | N24: University of Houston | O24: 6 | P24: Gulf of Mexico | Q24: 14.1 | R24: =IF(OR(AND(J24 > 15, B24 = "Infant"), AND(D24 = "Male", C24 > 0.75), OR(I24 > 0.8, G24 > 0.5), G24 > 1.2), "I", IF(OR(AND(I24 < 0.4, G24 < 0.4), AND(J24 > 15, D24 = "Male"), AND(J24 > 18, D24 = "Female"), C24 < 0.36), "II", "III")) -> II | S24: =IF(OR(AND(J24 > 15, B24 = "Infant"), AND(D24 = "Male", C24 > 0.75), OR(I24 > 0.8, G24 > 0.5), G24 > 1.2), (1 + (1/3)*(C24 - 0.5) + (1/3)*(D24 - 0.4) + (1/3)*(E24 - 0.4)) * F24 * 0.5 * 1.5, IF(OR(AND(I24 < 0.4, G24 < 0.4), AND(J24 > 15, D24 = "Male"), AND(J24 > 18, D24 = "Female"), C24 < 0.36), (1 + (1/3)*(C24 - 0.5) + (1/3)*(D24 - 0.4) + (1/3)*(E24 - 0.4)) * F24 * 0.5 * 0.8, (1 + (1/3)*(C24 - 0.5) + (1/3)*(D24 - 0.4) + (1/3)*(E24 - 0.4)) * F24 * 0.5)) -> 0.27718367
A25: 3034 | B25: F | C25: 0.535 | D25: 0.41 | E25: 0.12 | F25: 0.6835 | G25: 0.3125 | H25: 0.1655 | I25: 0.159 | J25: 8 | K25: 11 | L25: Naima | M25: Reyes | N25: University of Houston | O25: 4 | P25: Mid-Atlantic | Q25: 6.1 | R25: =IF(OR(AND(J25 > 15, B25 = "Infant"), AND(D25 = "Male", C25 > 0.75), OR(I25 > 0.8, G25 > 0.5), G25 > 1.2), "I", IF(OR(AND(I25 < 0.4, G25 < 0.4), AND(J25 > 15, D25 = "Male"), AND(J25 > 18, D25 = "Female"), C25 < 0.36), "II", "III")) -> II | S25: =IF(OR(AND(J25 > 15, B25 = "Infant"), AND(D25 = "Male", C25 > 0.75), OR(I25 > 0.8, G25 > 0.5), G25 > 1.2), (1 + (1/3)*(C25 - 0.5) + (1/3)*(D25 - 0.4) + (1/3)*(E25 - 0.4)) * F25 * 0.5 * 1.5, IF(OR(AND(I25 < 0.4, G25 < 0.4), AND(J25 > 15, D25 = "Male"), AND(J25 > 18, D25 = "Female"), C25 < 0.36), (1 + (1/3)*(C25 - 0.5) + (1/3)*(D25 - 0.4) + (1/3)*(E25 - 0.4)) * F25 * 0.5 * 0.8, (1 + (1/3)*(C25 - 0.5) + (1/3)*(D25 - 0.4) + (1/3)*(E25 - 0.4)) * F25 * 0.5)) -> 0.25198367
A26: 3032 | B26: F | C26: 0.525 | D26: 0.4 | E26: 0.11 | F26: 0.6275 | G26: 0.3015 | H26: 0.126 | I26: 0.18 | J26: 8 | K26: 3 | L26: Inaya | M26: Bernard | N26: Stanford University | O26: 3 | P26: Northeast | Q26: 3.6 | R26: =IF(OR(AND(J26 > 15, B26 = "Infant"), AND(D26 = "Male", C26 > 0.75), OR(I26 > 0.8, G26 > 0.5), G26 > 1.2), "I", IF(OR(AND(I26 < 0.4, G26 < 0.4), AND(J26 > 15, D26 = "Male"), AND(J26 > 18, D26 = "Female"), C26 < 0.36), "II", "III")) -> II | S26: =IF(OR(AND(J26 > 15, B26 = "Infant"), AND(D26 = "Male", C26 > 0.75), OR(I26 > 0.8, G26 > 0.5), G26 > 1.2), (1 + (1/3)*(C26 - 0.5) + (1/3)*(D26 - 0.4) + (1/3)*(E26 - 0.4)) * F26 * 0.5 * 1.5, IF(OR(AND(I26 < 0.4, G26 < 0.4), AND(J26 > 15, D26 = "Male"), AND(J26 > 18, D26 = "Female"), C26 < 0.36), (1 + (1/3)*(C26 - 0.5) + (1/3)*(D26 - 0.4) + (1/3)*(E26 - 0.4)) * F26 * 0.5 * 0.8, (1 + (1/3)*(C26 - 0.5) + (1/3)*(D26 - 0.4) + (1/3)*(E26 - 0.4)) * F26 * 0.5)) -> 0.22882833
A27: 2224 | B27: F | C27: 0.555 | D27: 0.455 | E27: 0.18 | F27: 0.958 | G27: 0.296 | H27: 0.195 | I27: 0.39 | J27: 14 | K27: 8 | L27: Kali | M27: Metcalfe | N27: Mote Marine Laboratory | O27: 7 | P27: Great Lakes | Q27: 2.5 | R27: =IF(OR(AND(J27 > 15, B27 = "Infant"), AND(D27 = "Male", C27 > 0.75), OR(I27 > 0.8, G27 > 0.5), G27 > 1.2), "I", IF(OR(AND(I27 < 0.4, G27 < 0.4), AND(J27 > 15, D27 = "Male"), AND(J27 > 18, D27 = "Female"), C27 < 0.36), "II", "III")) -> II | S27: =IF(OR(AND(J27 > 15, B27 = "Infant"), AND(D27 = "Male", C27 > 0.75), OR(I27 > 0.8, G27 > 0.5), G27 > 1.2), (1 + (1/3)*(C27 - 0.5) + (1/3)*(D27 - 0.4) + (1/3)*(E27 - 0.4)) * F27 * 0.5 * 1.5, IF(OR(AND(I27 < 0.4, G27 < 0.4), AND(J27 > 15, D27 = "Male"), AND(J27 > 18, D27 = "Female"), C27 < 0.36), (1 + (1/3)*(C27 - 0.5) + (1/3)*(D27 - 0.4) + (1/3)*(E27 - 0.4)) * F27 * 0.5 * 0.8, (1 + (1/3)*(C27 - 0.5) + (1/3)*(D27 - 0.4) + (1/3)*(E27 - 0.4)) * F27 * 0.5)) -> 0.36914933
A28: 953 | B28: F | C28: 0.48 | D28: 0.365 | E28: 0.12 | F28: 0.6015 | G28: 0.312 | H28: 0.117 | I28: 0.14 | J28: 7 | K28: 6 | L28: Martin | M28: Gaines | N28: San Diego State University | O28: 4 | P28: Mid-Atlantic | Q28: 6.1 | R28: =IF(OR(AND(J28 > 15, B28 = "Infant"), AND(D28 = "Male", C28 > 0.75), OR(I28 > 0.8, G28 > 0.5), G28 > 1.2), "I", IF(OR(AND(I28 < 0.4, G28 < 0.4), AND(J28 > 15, D28 = "Male"), AND(J28 > 18, D28 = "Female"), C28 < 0.36), "II", "III")) -> II | S28: =IF(OR(AND(J28 > 15, B28 = "Infant"), AND(D28 = "Male", C28 > 0.75), OR(I28 > 0.8, G28 > 0.5), G28 > 1.2), (1 + (1/3)*(C28 - 0.5) + (1/3)*(D28 - 0.4) + (1/3)*(E28 - 0.4)) * F28 * 0.5 * 1.5, IF(OR(AND(I28 < 0.4, G28 < 0.4), AND(J28 > 15, D28 = "Male"), AND(J28 > 18, D28 = "Female"), C28 < 0.36), (1 + (1/3)*(C28 - 0.5) + (1/3)*(D28 - 0.4) + (1/3)*(E28 - 0.4)) * F28 * 0.5 * 0.8, (1 + (1/3)*(C28 - 0.5) + (1/3)*(D28 - 0.4) + (1/3)*(E28 - 0.4)) * F28 * 0.5)) -> 0.213733
A29: 2649 | B29: F | C29: 0.5 | D29: 0.38 | E29: 0.12 | F29: 0.5765 | G29: 0.273 | H29: 0.135 | I29: 0.145 | J29: 9 | K29: 12 | L29: Rebecca | M29: Bennett | N29: University of Houston | O29: 7 | P29: Great Lakes | Q29: 2.5 | R29: =IF(OR(AND(J29 > 15, B29 = "Infant"), AND(D29 = "Male", C29 > 0.75), OR(I29 > 0.8, G29 > 0.5), G29 > 1.2), "I", IF(OR(AND(I29 < 0.4, G29 < 0.4), AND(J29 > 15, D29 = "Male"), AND(J29 > 18, D29 = "Female"), C29 < 0.36), "II", "III")) -> II | S29: =IF(OR(AND(J29 > 15, B29 = "Infant"), AND(D29 = "Male", C29 > 0.75), OR(I29 > 0.8, G29 > 0.5), G29 > 1.2), (1 + (1/3)*(C29 - 0.5) + (1/3)*(D29 - 0.4) + (1/3)*(E29 - 0.4)) * F29 * 0.5 * 1.5, IF(OR(AND(I29 < 0.4, G29 < 0.4), AND(J29 > 15, D29 = "Male"), AND(J29 > 18, D29 = "Female"), C29 < 0.36), (1 + (1/3)*(C29 - 0.5) + (1/3)*(D29 - 0.4) + (1/3)*(E29 - 0.4)) * F29 * 0.5 * 0.8, (1 + (1/3)*(C29 - 0.5) + (1/3)*(D29 - 0.4) + (1/3)*(E29 - 0.4)) * F29 * 0.5)) -> 0.20754
A30: 932 | B30: F | C30: 0.445 | D30: 0.335 | E30: 0.11 | F30: 0.4355 | G30: 0.2025 | H30: 0.1095 | I30: 0.1195 | J30: 6 | K30: 15 | L30: Conan | M30: Dalton | N30: University of Houston | O30: 5 | P30: Southeast | Q30: 12.8 | R30: =IF(OR(AND(J30 > 15, B30 = "Infant"), AND(D30 = "Male", C30 > 0.75), OR(I30 > 0.8, G30 > 0.5), G30 > 1.2), "I", IF(OR(AND(I30 < 0.4, G30 < 0.4), AND(J30 > 15, D30 = "Male"), AND(J30 > 18, D30 = "Female"), C30 < 0.36), "II", "III")) -> II | S30: =IF(OR(AND(J30 > 15, B30 = "Infant"), AND(D30 = "Male", C30 > 0.75), OR(I30 > 0.8, G30 > 0.5), G30 > 1.2), (1 + (1/3)*(C30 - 0.5) + (1/3)*(D30 - 0.4) + (1/3)*(E30 - 0.4)) * F30 * 0.5 * 1.5, IF(OR(AND(I30 < 0.4, G30 < 0.4), AND(J30 > 15, D30 = "Male"), AND(J30 > 18, D30 = "Female"), C30 < 0.36), (1 + (1/3)*(C30 - 0.5) + (1/3)*(D30 - 0.4) + (1/3)*(E30 - 0.4)) * F30 * 0.5 * 0.8, (1 + (1/3)*(C30 - 0.5) + (1/3)*(D30 - 0.4) + (1/3)*(E30 - 0.4)) * F30 * 0.5)) -> 0.15039267
A31: 3844 | B31: F | C31: 0.575 | D31: 0.45 | E31: 0.16 | F31: 0.955 | G31: 0.44 | H31: 0.1685 | I31: 0.27 | J31: 16 | K31: 3 | L31: Inaya | M31: Bernard | N31: Stanford University | O31: 3 | P31: Northeast | Q31: 3.6 | R31: =IF(OR(AND(J31 > 15, B31 = "Infant"), AND(D31 = "Male", C31 > 0.75), OR(I31 > 0.8, G31 > 0.5), G31 > 1.2), "I", IF(OR(AND(I31 < 0.4, G31 < 0.4), AND(J31 > 15, D31 = "Male"), AND(J31 > 18, D31 = "Female"), C31 < 0.36), "II", "III")) -> III | S31: =IF(OR(AND(J31 > 15, B31 = "Infant"), AND(D31 = "Male", C31 > 0.75), OR(I31 > 0.8, G31 > 0.5), G31 > 1.2), (1 + (1/3)*(C31 - 0.5) + (1/3)*(D31 - 0.4) + (1/3)*(E31 - 0.4)) * F31 * 0.5 * 1.5, IF(OR(AND(I31 < 0.4, G31 < 0.4), AND(J31 > 15, D31 = "Male"), AND(J31 > 18, D31 = "Female"), C31 < 0.36), (1 + (1/3)*(C31 - 0.5) + (1/3)*(D31 - 0.4) + (1/3)*(E31 - 0.4)) * F31 * 0.5 * 0.8, (1 + (1/3)*(C31 - 0.5) + (1/3)*(D31 - 0.4) + (1/3)*(E31 - 0.4)) * F31 * 0.5)) -> 0.45919583
A32: 2065 | B32: F | C32: 0.535 | D32: 0.42 | E32: 0.125 | F32: 0.738 | G32: 0.355 | H32: 0.1895 | I32: 0.1795 | J32: 8 | K32: 12 | L32: Rebecca | M32: Bennett | N32: University of Houston | O32: 7 | P32: Great Lakes | Q32: 2.5 | R32: =IF(OR(AND(J32 > 15, B32 = "Infant"), AND(D32 = "Male", C32 > 0.75), OR(I32 > 0.8, G32 > 0.5), G32 > 1.2), "I", IF(OR(AND(I32 < 0.4, G32 < 0.4), AND(J32 > 15, D32 = "Male"), AND(J32 > 18, D32 = "Female"), C32 < 0.36), "II", "III")) -> II | S32: =IF(OR(AND(J32 > 15, B32 = "Infant"), AND(D32 = "Male", C32 > 0.75), OR(I32 > 0.8, G32 > 0.5), G32 > 1.2), (1 + (1/3)*(C32 - 0.5) + (1/3)*(D32 - 0.4) + (1/3)*(E32 - 0.4)) * F32 * 0.5 * 1.5, IF(OR(AND(I32 < 0.4, G32 < 0.4), AND(J32 > 15, D32 = "Male"), AND(J32 > 18, D32 = "Female"), C32 < 0.36), (1 + (1/3)*(C32 - 0.5) + (1/3)*(D32 - 0.4) + (1/3)*(E32 - 0.4)) * F32 * 0.5 * 0.8, (1 + (1/3)*(C32 - 0.5) + (1/3)*(D32 - 0.4) + (1/3)*(E32 - 0.4)) * F32 * 0.5)) -> 0.273552
... A1001: 2207 | B1001: M | C1001: 0.29 | D1001: 0.225 | E1001: 0.075 | F1001: 0.14 | G1001: 0.0515 | H1001: 0.0235 | I1001: 0.04 | J1001: 5 | K1001: 3 | L1001: Inaya | M1001: Bernard | N1001: Stanford University | O1001: 5 | P1001: Southeast | Q1001: 12.8 | R1001: =IF(OR(AND(J1001 > 15, B1001 = "Infant"), AND(D1001 = "Male", C1001 > 0.75), OR(I1001 > 0.8, G1001 > 0.5), G1001 > 1.2), "I", IF(OR(AND(I1001 < 0.4, G1001 < 0.4), AND(J1001 > 15, D1001 = "Male"), AND(J1001 > 18, D1001 = "Female"), C1001 < 0.36), "II", "III")) -> II | S1001: =IF(OR(AND(J1001 > 15, B1001 = "Infant"), AND(D1001 = "Male", C1001 > 0.75), OR(I1001 > 0.8, G1001 > 0.5), G1001 > 1.2), (1 + (1/3)*(C1001 - 0.5) + (1/3)*(D1001 - 0.4) + (1/3)*(E1001 - 0.4)) * F1001 * 0.5 * 1.5, IF(OR(AND(I1001 < 0.4, G1001 < 0.4), AND(J1001 > 15, D1001 = "Male"), AND(J1001 > 18, D1001 = "Female"), C1001 < 0.36), (1 + (1/3)*(C1001 - 0.5) + (1/3)*(D1001 - 0.4) + (1/3)*(E1001 - 0.4)) * F1001 * 0.5 * 0.8, (1 + (1/3)*(C1001 - 0.5) + (1/3)*(D1001 - 0.4) + (1/3)*(E1001 - 0.4)) * F1001 * 0.5)) -> 0.042746667
B1002: M

Sheet Statistics
A1: Attribute | B1: Mean | C1: Variance | D1: Minimum | E1: Maximum
A2: Length | B2: 0.4903 | C2: 0.0112 | D2: 0.11 | E2: 0.72
A3: Diameter | B3: 0.3793 | C3: 0.0076 | D3: 0.09 | E3: 0.565
A4: Height | B4: 0.1279 | C4: 0.0011 | D4: 0 | E4: 0.23
A5: Whole_weight | B5: 0.6465 | C5: 0.1116 | D5: 0.008 | E5: 1.2435
A6: Shucked_weight | B6: 0.2784 | C6: 0.0227 | D6: 0.0025 | E6: 0.707
A7: Viscera_weight | B7: 0.1426 | C7: 0.006 | D7: 0.002 | E7: 0.4365
A8: Shell_weight | B8: 0.1889 | C8: 0.0095 | D8: 0.003 | E8: 0.525
A9: Rings | B9: 9.437 | C9: 9.2012 | D9: 3 | E9: 27

Sheet Sheet1

Sheet Search functions
A1: Column1 | B1: Column2
A2: Enter Abalon ID | B2: 1319
A5: Gender | B5: Length | C5: Diameter | D5: Height | E5: Whole Weight | F5: Shucked_weight | G5: Viscera_weight | H5: Shell_weight | I5: Rings | J5: Collector | K5: Collector_First | L5: Collector_last | M5: Collector_organization | N5: Water | O5: Water_region | P5: Feb_temp
